Workbook

Sheet Requerimiento_Cab
A1: Secuencia | B1: CompaniaNombre | C1: ClasificacionNombre | D1: Dirigido a | E1: Almacen | F1: Departamento | G1: CentroCostos | H1: Placa | I1: Proyecto | J1: UnidadNegocio | K1: Dir. Destino | L1: Comentario | M1: CampoReferencia | N1: Moneda
A2: =(IF(LEN(B2)>0,ROW(A2)-1,"")) -> 1 | B2: GRUPO TRANSPESA SAC | C2: Servicios | D2: Compras | E2: Almacén Commodities | F2: OPERACIONES | G2: Tractos | H2: T8H889 | I2: =IF(ISBLANK(Requerimiento_Cab!H2),"",VLOOKUP(Requerimiento_Cab!H2,Tabla1[#All],2,FALSE)) -> 1031100267 | J2: Servicio de Transporte de Carg | K2: Camiones | L2: PEAJES DEL 23.01.23 AL 31.01.23 F030 - 104882 | M2: CONTROL DE FLOTA | N2: LO
A21: =(IF(LEN(B21)>0,ROW(A21)-1,""))
A22: =(IF(LEN(B22)>0,ROW(A22)-1,""))
A23: =(IF(LEN(B23)>0,ROW(A23)-1,""))
A24: =(IF(LEN(B24)>0,ROW(A24)-1,""))
A25: =(IF(LEN(B25)>0,ROW(A25)-1,""))
A26: =(IF(LEN(B26)>0,ROW(A26)-1,""))
A27: =(IF(LEN(B27)>0,ROW(A27)-1,""))
A28: =(IF(LEN(B28)>0,ROW(A28)-1,""))
A29: =(IF(LEN(B29)>0,ROW(A29)-1,""))
A30: =(IF(LEN(B30)>0,ROW(A30)-1,""))
A31: =(IF(LEN(B31)>0,ROW(A31)-1,""))
A32: =(IF(LEN(B32)>0,ROW(A32)-1,""))
... A800: =(IF(LEN(B800)>0,ROW(A800)-1,""))

Sheet GenerarDataCabecera
A1: Secuencia | B1: RequisicionNumero | C1: CompaniaSocio | D1: Clasificacion | E1: ComprasAlmacenFlag | F1: AlmacenCodigo | G1: MonedaCodigo | H1: PreparadaPor | I1: Departamento | J1: PrioridadCodigo | K1: DefaultPrime | L1: DefaultAfe | M1: CuantiaMonetariaPendienteFlag | N1: UnidadNegocio | O1: UnidadReplicacion | P1: LocalForeignFlag | Q1: DireccionDestino | R1: Comentarios | S1: Estado | T1: UltimoUsuario | U1: UltimoUsuarioNumero | V1: TransaccionOperacion | W1: RevisionTecnicaPendienteFlag | X1: DefaultCampoReferencia | Y1: UnidadNegocioCompra
A2: =IF(LEN(Requerimiento_Cab!A2)>0,Requerimiento_Cab!A2,"") -> 1 | B2: =(IF(LEN(C2)>0,ROW(B2)-1,"")) -> 1 | C2: =IF(ISBLANK(Requerimiento_Cab!B2),"",VLOOKUP(Requerimiento_Cab!B2,Tabla3[#All],2,FALSE)) -> 10000000 | D2: =IF(ISBLANK(Requerimiento_Cab!C2),"",VLOOKUP(Requerimiento_Cab!C2,Tabla4[#All],2,FALSE)) -> SER | E2: =IF(ISBLANK(Requerimiento_Cab!D2),"",VLOOKUP(Requerimiento_Cab!D2,Tabla5[#All],2,FALSE)) -> C | F2: =IF(ISBLANK(Requerimiento_Cab!E2),"",VLOOKUP(Requerimiento_Cab!E2,Tabla6[#All],2,FALSE)) -> A007 | G2: =IF(LEN(Requerimiento_Cab!N2)>0,Requerimiento_Cab!N2,"") -> LO | H2: =IF(LEN(C2)>0,"0","") -> 0 | I2: =IF(ISBLANK(Requerimiento_Cab!F2),"",VLOOKUP(Requerimiento_Cab!F2,Tabla7[#All],2,FALSE)) -> OP | J2: =IF(LEN(C2)>0,"1","") -> 1 | K2: =IF(ISBLANK(Requerimiento_Cab!G2),"",VLOOKUP(Requerimiento_Cab!G2,Tabla8[#All],2,FALSE)) -> 010201 | L2: =IF(ISBLANK(Requerimiento_Cab!H2),"",VLOOKUP(Requerimiento_Cab!H2,Tabla1[#All],2,FALSE)) -> 1031100267 | M2: =IF(LEN(C2)>0,"N","") -> N | N2: =IF(ISBLANK(Requerimiento_Cab!J2),"",VLOOKUP(Requerimiento_Cab!J2,Tabla9[#All],2,FALSE)) -> TRAN | O2: =IF(LEN(C2)>0,"TRUJ","") -> TRUJ | P2: =IF(LEN(C2)>0,"L","") -> L | Q2: =IF(ISBLANK(Requerimiento_Cab!K2),"",VLOOKUP(Requerimiento_Cab!K2,Tabla10[#All],2,FALSE)) -> Costos | R2: =IF(LEN(Requerimiento_Cab!L2)>0,Requerimiento_Cab!L2,"") -> PEAJES DEL 23.01.23 AL 31.01.23 F030 - 104882 | S2: =IF(LEN(C2)>0,"RV","") -> RV | T2: =IF(LEN(C2)>0,"DEMO","") -> DEMO | U2: =IF(LEN(C2)>0,"0","") -> 0 | V2: =IF(ISBLANK(Requerimiento_Cab!F2),"",VLOOKUP(Requerimiento_Cab!F2,Tabla7[#All],2,FALSE)) -> OP | W2: =IF(LEN(C2)>0,"N","") -> N | X2: =IF(ISBLANK(Requerimiento_Cab!M2),"",VLOOKUP(Requerimiento_Cab!M2,Tabla2[#All],2,FALSE)) -> 108 | Y2: =IF(ISBLANK(Requerimiento_Cab!J2),"",VLOOKUP(Requerimiento_Cab!J2,Tabla9[#All],2,FALSE)) -> TRAN
A3: =IF(LEN(Requerimiento_Cab!A3)>0,Requerimiento_Cab!A3,"") | B3: =(IF(LEN(C3)>0,ROW(B3)-1,"")) | C3: =IF(ISBLANK(Requerimiento_Cab!B3),"",VLOOKUP(Requerimiento_Cab!B3,Tabla3[#All],2,FALSE)) | D3: =IF(ISBLANK(Requerimiento_Cab!C3),"",VLOOKUP(Requerimiento_Cab!C3,Tabla4[#All],2,FALSE)) | E3: =IF(ISBLANK(Requerimiento_Cab!D3),"",VLOOKUP(Requerimiento_Cab!D3,Tabla5[#All],2,FALSE)) | F3: =IF(ISBLANK(Requerimiento_Cab!E3),"",VLOOKUP(Requerimiento_Cab!E3,Tabla6[#All],2,FALSE)) | G3: =IF(LEN(C3)>0,"LO","") | H3: =IF(LEN(C3)>0,"0","") | I3: =IF(ISBLANK(Requerimiento_Cab!F3),"",VLOOKUP(Requerimiento_Cab!F3,Tabla7[#All],2,FALSE)) | J3: =IF(LEN(C3)>0,"1","") | K3: =IF(ISBLANK(Requerimiento_Cab!G3),"",VLOOKUP(Requerimiento_Cab!G3,Tabla8[#All],2,FALSE)) | L3: =IF(ISBLANK(Requerimiento_Cab!H3),"",VLOOKUP(Requerimiento_Cab!H3,Tabla1[#All],2,FALSE)) | M3: =IF(LEN(C3)>0,"N","") | N3: =IF(ISBLANK(Requerimiento_Cab!J3),"",VLOOKUP(Requerimiento_Cab!J3,Tabla9[#All],2,FALSE)) | O3: =IF(LEN(C3)>0,"TRUJ","") | P3: =IF(LEN(C3)>0,"L","") | Q3: =IF(ISBLANK(Requerimiento_Cab!K3),"",VLOOKUP(Requerimiento_Cab!K3,Tabla10[#All],2,FALSE)) | R3: =IF(LEN(Requerimiento_Cab!L3)>0,Requerimiento_Cab!L3,"") | S3: =IF(LEN(C3)>0,"RV","") | T3: =IF(LEN(C3)>0,"DEMO","") | U3: =IF(LEN(C3)>0,"0","") | V3: =IF(ISBLANK(Requerimiento_Cab!F3),"",VLOOKUP(Requerimiento_Cab!F3,Tabla7[#All],2,FALSE)) | W3: =IF(LEN(C3)>0,"N","") | X3: =IF(ISBLANK(Requerimiento_Cab!M3),"",VLOOKUP(Requerimiento_Cab!M3,Tabla2[#All],2,FALSE)) | Y3: =IF(ISBLANK(Requerimiento_Cab!J3),"",VLOOKUP(Requerimiento_Cab!J3,Tabla9[#All],2,FALSE))
A4: =IF(LEN(Requerimiento_Cab!A4)>0,Requerimiento_Cab!A4,"") | B4: =(IF(LEN(C4)>0,ROW(B4)-1,"")) | C4: =IF(ISBLANK(Requerimiento_Cab!B4),"",VLOOKUP(Requerimiento_Cab!B4,Tabla3[#All],2,FALSE)) | D4: =IF(ISBLANK(Requerimiento_Cab!C4),"",VLOOKUP(Requerimiento_Cab!C4,Tabla4[#All],2,FALSE)) | E4: =IF(ISBLANK(Requerimiento_Cab!D4),"",VLOOKUP(Requerimiento_Cab!D4,Tabla5[#All],2,FALSE)) | F4: =IF(ISBLANK(Requerimiento_Cab!E4),"",VLOOKUP(Requerimiento_Cab!E4,Tabla6[#All],2,FALSE)) | G4: =IF(LEN(C4)>0,"LO","") | H4: =IF(LEN(C4)>0,"0","") | I4: =IF(ISBLANK(Requerimiento_Cab!F4),"",VLOOKUP(Requerimiento_Cab!F4,Tabla7[#All],2,FALSE)) | J4: =IF(LEN(C4)>0,"1","") | K4: =IF(ISBLANK(Requerimiento_Cab!G4),"",VLOOKUP(Requerimiento_Cab!G4,Tabla8[#All],2,FALSE)) | L4: =IF(ISBLANK(Requerimiento_Cab!H4),"",VLOOKUP(Requerimiento_Cab!H4,Tabla1[#All],2,FALSE)) | M4: =IF(LEN(C4)>0,"N","") | N4: =IF(ISBLANK(Requerimiento_Cab!J4),"",VLOOKUP(Requerimiento_Cab!J4,Tabla9[#All],2,FALSE)) | O4: =IF(LEN(C4)>0,"TRUJ","") | P4: =IF(LEN(C4)>0,"L","") | Q4: =IF(ISBLANK(Requerimiento_Cab!K4),"",VLOOKUP(Requerimiento_Cab!K4,Tabla10[#All],2,FALSE)) | R4: =IF(LEN(Requerimiento_Cab!L4)>0,Requerimiento_Cab!L4,"") | S4: =IF(LEN(C4)>0,"RV","") | T4: =IF(LEN(C4)>0,"DEMO","") | U4: =IF(LEN(C4)>0,"0","") | V4: =IF(ISBLANK(Requerimiento_Cab!F4),"",VLOOKUP(Requerimiento_Cab!F4,Tabla7[#All],2,FALSE)) | W4: =IF(LEN(C4)>0,"N","") | X4: =IF(ISBLANK(Requerimiento_Cab!M4),"",VLOOKUP(Requerimiento_Cab!M4,Tabla2[#All],2,FALSE)) | Y4: =IF(ISBLANK(Requerimiento_Cab!J4),"",VLOOKUP(Requerimiento_Cab!J4,Tabla9[#All],2,FALSE))
A5: =IF(LEN(Requerimiento_Cab!A5)>0,Requerimiento_Cab!A5,"") | B5: =(IF(LEN(C5)>0,ROW(B5)-1,"")) | C5: =IF(ISBLANK(Requerimiento_Cab!B5),"",VLOOKUP(Requerimiento_Cab!B5,Tabla3[#All],2,FALSE)) | D5: =IF(ISBLANK(Requerimiento_Cab!C5),"",VLOOKUP(Requerimiento_Cab!C5,Tabla4[#All],2,FALSE)) | E5: =IF(ISBLANK(Requerimiento_Cab!D5),"",VLOOKUP(Requerimiento_Cab!D5,Tabla5[#All],2,FALSE)) | F5: =IF(ISBLANK(Requerimiento_Cab!E5),"",VLOOKUP(Requerimiento_Cab!E5,Tabla6[#All],2,FALSE)) | G5: =IF(LEN(C5)>0,"LO","") | H5: =IF(LEN(C5)>0,"0","") | I5: =IF(ISBLANK(Requerimiento_Cab!F5),"",VLOOKUP(Requerimiento_Cab!F5,Tabla7[#All],2,FALSE)) | J5: =IF(LEN(C5)>0,"1","") | K5: =IF(ISBLANK(Requerimiento_Cab!G5),"",VLOOKUP(Requerimiento_Cab!G5,Tabla8[#All],2,FALSE)) | L5: =IF(ISBLANK(Requerimiento_Cab!H5),"",VLOOKUP(Requerimiento_Cab!H5,Tabla1[#All],2,FALSE)) | M5: =IF(LEN(C5)>0,"N","") | N5: =IF(ISBLANK(Requerimiento_Cab!J5),"",VLOOKUP(Requerimiento_Cab!J5,Tabla9[#All],2,FALSE)) | O5: =IF(LEN(C5)>0,"TRUJ","") | P5: =IF(LEN(C5)>0,"L","") | Q5: =IF(ISBLANK(Requerimiento_Cab!K5),"",VLOOKUP(Requerimiento_Cab!K5,Tabla10[#All],2,FALSE)) | R5: =IF(LEN(Requerimiento_Cab!L5)>0,Requerimiento_Cab!L5,"") | S5: =IF(LEN(C5)>0,"RV","") | T5: =IF(LEN(C5)>0,"DEMO","") | U5: =IF(LEN(C5)>0,"0","") | V5: =IF(ISBLANK(Requerimiento_Cab!F5),"",VLOOKUP(Requerimiento_Cab!F5,Tabla7[#All],2,FALSE)) | W5: =IF(LEN(C5)>0,"N","") | X5: =IF(ISBLANK(Requerimiento_Cab!M5),"",VLOOKUP(Requerimiento_Cab!M5,Tabla2[#All],2,FALSE)) | Y5: =IF(ISBLANK(Requerimiento_Cab!J5),"",VLOOKUP(Requerimiento_Cab!J5,Tabla9[#All],2,FALSE))
A6: =IF(LEN(Requerimiento_Cab!A6)>0,Requerimiento_Cab!A6,"") | B6: =(IF(LEN(C6)>0,ROW(B6)-1,"")) | C6: =IF(ISBLANK(Requerimiento_Cab!B6),"",VLOOKUP(Requerimiento_Cab!B6,Tabla3[#All],2,FALSE)) | D6: =IF(ISBLANK(Requerimiento_Cab!C6),"",VLOOKUP(Requerimiento_Cab!C6,Tabla4[#All],2,FALSE)) | E6: =IF(ISBLANK(Requerimiento_Cab!D6),"",VLOOKUP(Requerimiento_Cab!D6,Tabla5[#All],2,FALSE)) | F6: =IF(ISBLANK(Requerimiento_Cab!E6),"",VLOOKUP(Requerimiento_Cab!E6,Tabla6[#All],2,FALSE)) | G6: =IF(LEN(C6)>0,"LO","") | H6: =IF(LEN(C6)>0,"0","") | I6: =IF(ISBLANK(Requerimiento_Cab!F6),"",VLOOKUP(Requerimiento_Cab!F6,Tabla7[#All],2,FALSE)) | J6: =IF(LEN(C6)>0,"1","") | K6: =IF(ISBLANK(Requerimiento_Cab!G6),"",VLOOKUP(Requerimiento_Cab!G6,Tabla8[#All],2,FALSE)) | L6: =IF(ISBLANK(Requerimiento_Cab!H6),"",VLOOKUP(Requerimiento_Cab!H6,Tabla1[#All],2,FALSE)) | M6: =IF(LEN(C6)>0,"N","") | N6: =IF(ISBLANK(Requerimiento_Cab!J6),"",VLOOKUP(Requerimiento_Cab!J6,Tabla9[#All],2,FALSE)) | O6: =IF(LEN(C6)>0,"TRUJ","") | P6: =IF(LEN(C6)>0,"L","") | Q6: =IF(ISBLANK(Requerimiento_Cab!K6),"",VLOOKUP(Requerimiento_Cab!K6,Tabla10[#All],2,FALSE)) | R6: =IF(LEN(Requerimiento_Cab!L6)>0,Requerimiento_Cab!L6,"") | S6: =IF(LEN(C6)>0,"RV","") | T6: =IF(LEN(C6)>0,"DEMO","") | U6: =IF(LEN(C6)>0,"0","") | V6: =IF(ISBLANK(Requerimiento_Cab!F6),"",VLOOKUP(Requerimiento_Cab!F6,Tabla7[#All],2,FALSE)) | W6: =IF(LEN(C6)>0,"N","") | X6: =IF(ISBLANK(Requerimiento_Cab!M6),"",VLOOKUP(Requerimiento_Cab!M6,Tabla2[#All],2,FALSE)) | Y6: =IF(ISBLANK(Requerimiento_Cab!J6),"",VLOOKUP(Requerimiento_Cab!J6,Tabla9[#All],2,FALSE))
A7: =IF(LEN(Requerimiento_Cab!A7)>0,Requerimiento_Cab!A7,"") | B7: =(IF(LEN(C7)>0,ROW(B7)-1,"")) | C7: =IF(ISBLANK(Requerimiento_Cab!B7),"",VLOOKUP(Requerimiento_Cab!B7,Tabla3[#All],2,FALSE)) | D7: =IF(ISBLANK(Requerimiento_Cab!C7),"",VLOOKUP(Requerimiento_Cab!C7,Tabla4[#All],2,FALSE)) | E7: =IF(ISBLANK(Requerimiento_Cab!D7),"",VLOOKUP(Requerimiento_Cab!D7,Tabla5[#All],2,FALSE)) | F7: =IF(ISBLANK(Requerimiento_Cab!E7),"",VLOOKUP(Requerimiento_Cab!E7,Tabla6[#All],2,FALSE)) | G7: =IF(LEN(C7)>0,"LO","") | H7: =IF(LEN(C7)>0,"0","") | I7: =IF(ISBLANK(Requerimiento_Cab!F7),"",VLOOKUP(Requerimiento_Cab!F7,Tabla7[#All],2,FALSE)) | J7: =IF(LEN(C7)>0,"1","") | K7: =IF(ISBLANK(Requerimiento_Cab!G7),"",VLOOKUP(Requerimiento_Cab!G7,Tabla8[#All],2,FALSE)) | L7: =IF(ISBLANK(Requerimiento_Cab!H7),"",VLOOKUP(Requerimiento_Cab!H7,Tabla1[#All],2,FALSE)) | M7: =IF(LEN(C7)>0,"N","") | N7: =IF(ISBLANK(Requerimiento_Cab!J7),"",VLOOKUP(Requerimiento_Cab!J7,Tabla9[#All],2,FALSE)) | O7: =IF(LEN(C7)>0,"TRUJ","") | P7: =IF(LEN(C7)>0,"L","") | Q7: =IF(ISBLANK(Requerimiento_Cab!K7),"",VLOOKUP(Requerimiento_Cab!K7,Tabla10[#All],2,FALSE)) | R7: =IF(LEN(Requerimiento_Cab!L7)>0,Requerimiento_Cab!L7,"") | S7: =IF(LEN(C7)>0,"RV","") | T7: =IF(LEN(C7)>0,"DEMO","") | U7: =IF(LEN(C7)>0,"0","") | V7: =IF(ISBLANK(Requerimiento_Cab!F7),"",VLOOKUP(Requerimiento_Cab!F7,Tabla7[#All],2,FALSE)) | W7: =IF(LEN(C7)>0,"N","") | X7: =IF(ISBLANK(Requerimiento_Cab!M7),"",VLOOKUP(Requerimiento_Cab!M7,Tabla2[#All],2,FALSE)) | Y7: =IF(ISBLANK(Requerimiento_Cab!J7),"",VLOOKUP(Requerimiento_Cab!J7,Tabla9[#All],2,FALSE))
A8: =IF(LEN(Requerimiento_Cab!A8)>0,Requerimiento_Cab!A8,"") | B8: =(IF(LEN(C8)>0,ROW(B8)-1,"")) | C8: =IF(ISBLANK(Requerimiento_Cab!B8),"",VLOOKUP(Requerimiento_Cab!B8,Tabla3[#All],2,FALSE)) | D8: =IF(ISBLANK(Requerimiento_Cab!C8),"",VLOOKUP(Requerimiento_Cab!C8,Tabla4[#All],2,FALSE)) | E8: =IF(ISBLANK(Requerimiento_Cab!D8),"",VLOOKUP(Requerimiento_Cab!D8,Tabla5[#All],2,FALSE)) | F8: =IF(ISBLANK(Requerimiento_Cab!E8),"",VLOOKUP(Requerimiento_Cab!E8,Tabla6[#All],2,FALSE)) | G8: =IF(LEN(C8)>0,"LO","") | H8: =IF(LEN(C8)>0,"0","") | I8: =IF(ISBLANK(Requerimiento_Cab!F8),"",VLOOKUP(Requerimiento_Cab!F8,Tabla7[#All],2,FALSE)) | J8: =IF(LEN(C8)>0,"1","") | K8: =IF(ISBLANK(Requerimiento_Cab!G8),"",VLOOKUP(Requerimiento_Cab!G8,Tabla8[#All],2,FALSE)) | L8: =IF(ISBLANK(Requerimiento_Cab!H8),"",VLOOKUP(Requerimiento_Cab!H8,Tabla1[#All],2,FALSE)) | M8: =IF(LEN(C8)>0,"N","") | N8: =IF(ISBLANK(Requerimiento_Cab!J8),"",VLOOKUP(Requerimiento_Cab!J8,Tabla9[#All],2,FALSE)) | O8: =IF(LEN(C8)>0,"TRUJ","") | P8: =IF(LEN(C8)>0,"L","") | Q8: =IF(ISBLANK(Requerimiento_Cab!K8),"",VLOOKUP(Requerimiento_Cab!K8,Tabla10[#All],2,FALSE)) | R8: =IF(LEN(Requerimiento_Cab!L8)>0,Requerimiento_Cab!L8,"") | S8: =IF(LEN(C8)>0,"RV","") | T8: =IF(LEN(C8)>0,"DEMO","") | U8: =IF(LEN(C8)>0,"0","") | V8: =IF(ISBLANK(Requerimiento_Cab!F8),"",VLOOKUP(Requerimiento_Cab!F8,Tabla7[#All],2,FALSE)) | W8: =IF(LEN(C8)>0,"N","") | X8: =IF(ISBLANK(Requerimiento_Cab!M8),"",VLOOKUP(Requerimiento_Cab!M8,Tabla2[#All],2,FALSE)) | Y8: =IF(ISBLANK(Requerimiento_Cab!J8),"",VLOOKUP(Requerimiento_Cab!J8,Tabla9[#All],2,FALSE))
A9: =IF(LEN(Requerimiento_Cab!A9)>0,Requerimiento_Cab!A9,"") | B9: =(IF(LEN(C9)>0,ROW(B9)-1,"")) | C9: =IF(ISBLANK(Requerimiento_Cab!B9),"",VLOOKUP(Requerimiento_Cab!B9,Tabla3[#All],2,FALSE)) | D9: =IF(ISBLANK(Requerimiento_Cab!C9),"",VLOOKUP(Requerimiento_Cab!C9,Tabla4[#All],2,FALSE)) | E9: =IF(ISBLANK(Requerimiento_Cab!D9),"",VLOOKUP(Requerimiento_Cab!D9,Tabla5[#All],2,FALSE)) | F9: =IF(ISBLANK(Requerimiento_Cab!E9),"",VLOOKUP(Requerimiento_Cab!E9,Tabla6[#All],2,FALSE)) | G9: =IF(LEN(C9)>0,"LO","") | H9: =IF(LEN(C9)>0,"0","") | I9: =IF(ISBLANK(Requerimiento_Cab!F9),"",VLOOKUP(Requerimiento_Cab!F9,Tabla7[#All],2,FALSE)) | J9: =IF(LEN(C9)>0,"1","") | K9: =IF(ISBLANK(Requerimiento_Cab!G9),"",VLOOKUP(Requerimiento_Cab!G9,Tabla8[#All],2,FALSE)) | L9: =IF(ISBLANK(Requerimiento_Cab!H9),"",VLOOKUP(Requerimiento_Cab!H9,Tabla1[#All],2,FALSE)) | M9: =IF(LEN(C9)>0,"N","") | N9: =IF(ISBLANK(Requerimiento_Cab!J9),"",VLOOKUP(Requerimiento_Cab!J9,Tabla9[#All],2,FALSE)) | O9: =IF(LEN(C9)>0,"TRUJ","") | P9: =IF(LEN(C9)>0,"L","") | Q9: =IF(ISBLANK(Requerimiento_Cab!K9),"",VLOOKUP(Requerimiento_Cab!K9,Tabla10[#All],2,FALSE)) | R9: =IF(LEN(Requerimiento_Cab!L9)>0,Requerimiento_Cab!L9,"") | S9: =IF(LEN(C9)>0,"RV","") | T9: =IF(LEN(C9)>0,"DEMO","") | U9: =IF(LEN(C9)>0,"0","") | V9: =IF(ISBLANK(Requerimiento_Cab!F9),"",VLOOKUP(Requerimiento_Cab!F9,Tabla7[#All],2,FALSE)) | W9: =IF(LEN(C9)>0,"N","") | X9: =IF(ISBLANK(Requerimiento_Cab!M9),"",VLOOKUP(Requerimiento_Cab!M9,Tabla2[#All],2,FALSE)) | Y9: =IF(ISBLANK(Requerimiento_Cab!J9),"",VLOOKUP(Requerimiento_Cab!J9,Tabla9[#All],2,FALSE))
A10: =IF(LEN(Requerimiento_Cab!A10)>0,Requerimiento_Cab!A10,"") | B10: =(IF(LEN(C10)>0,ROW(B10)-1,"")) | C10: =IF(ISBLANK(Requerimiento_Cab!B10),"",VLOOKUP(Requerimiento_Cab!B10,Tabla3[#All],2,FALSE)) | D10: =IF(ISBLANK(Requerimiento_Cab!C10),"",VLOOKUP(Requerimiento_Cab!C10,Tabla4[#All],2,FALSE)) | E10: =IF(ISBLANK(Requerimiento_Cab!D10),"",VLOOKUP(Requerimiento_Cab!D10,Tabla5[#All],2,FALSE)) | F10: =IF(ISBLANK(Requerimiento_Cab!E10),"",VLOOKUP(Requerimiento_Cab!E10,Tabla6[#All],2,FALSE)) | G10: =IF(LEN(C10)>0,"LO","") | H10: =IF(LEN(C10)>0,"0","") | I10: =IF(ISBLANK(Requerimiento_Cab!F10),"",VLOOKUP(Requerimiento_Cab!F10,Tabla7[#All],2,FALSE)) | J10: =IF(LEN(C10)>0,"1","") | K10: =IF(ISBLANK(Requerimiento_Cab!G10),"",VLOOKUP(Requerimiento_Cab!G10,Tabla8[#All],2,FALSE)) | L10: =IF(ISBLANK(Requerimiento_Cab!H10),"",VLOOKUP(Requerimiento_Cab!H10,Tabla1[#All],2,FALSE)) | M10: =IF(LEN(C10)>0,"N","") | N10: =IF(ISBLANK(Requerimiento_Cab!J10),"",VLOOKUP(Requerimiento_Cab!J10,Tabla9[#All],2,FALSE)) | O10: =IF(LEN(C10)>0,"TRUJ","") | P10: =IF(LEN(C10)>0,"L","") | Q10: =IF(ISBLANK(Requerimiento_Cab!K10),"",VLOOKUP(Requerimiento_Cab!K10,Tabla10[#All],2,FALSE)) | R10: =IF(LEN(Requerimiento_Cab!L10)>0,Requerimiento_Cab!L10,"") | S10: =IF(LEN(C10)>0,"RV","") | T10: =IF(LEN(C10)>0,"DEMO","") | U10: =IF(LEN(C10)>0,"0","") | V10: =IF(ISBLANK(Requerimiento_Cab!F10),"",VLOOKUP(Requerimiento_Cab!F10,Tabla7[#All],2,FALSE)) | W10: =IF(LEN(C10)>0,"N","") | X10: =IF(ISBLANK(Requerimiento_Cab!M10),"",VLOOKUP(Requerimiento_Cab!M10,Tabla2[#All],2,FALSE)) | Y10: =IF(ISBLANK(Requerimiento_Cab!J10),"",VLOOKUP(Requerimiento_Cab!J10,Tabla9[#All],2,FALSE))
A11: =IF(LEN(Requerimiento_Cab!A11)>0,Requerimiento_Cab!A11,"") | B11: =(IF(LEN(C11)>0,ROW(B11)-1,"")) | C11: =IF(ISBLANK(Requerimiento_Cab!B11),"",VLOOKUP(Requerimiento_Cab!B11,Tabla3[#All],2,FALSE)) | D11: =IF(ISBLANK(Requerimiento_Cab!C11),"",VLOOKUP(Requerimiento_Cab!C11,Tabla4[#All],2,FALSE)) | E11: =IF(ISBLANK(Requerimiento_Cab!D11),"",VLOOKUP(Requerimiento_Cab!D11,Tabla5[#All],2,FALSE)) | F11: =IF(ISBLANK(Requerimiento_Cab!E11),"",VLOOKUP(Requerimiento_Cab!E11,Tabla6[#All],2,FALSE)) | G11: =IF(LEN(C11)>0,"LO","") | H11: =IF(LEN(C11)>0,"0","") | I11: =IF(ISBLANK(Requerimiento_Cab!F11),"",VLOOKUP(Requerimiento_Cab!F11,Tabla7[#All],2,FALSE)) | J11: =IF(LEN(C11)>0,"1","") | K11: =IF(ISBLANK(Requerimiento_Cab!G11),"",VLOOKUP(Requerimiento_Cab!G11,Tabla8[#All],2,FALSE)) | L11: =IF(ISBLANK(Requerimiento_Cab!H11),"",VLOOKUP(Requerimiento_Cab!H11,Tabla1[#All],2,FALSE)) | M11: =IF(LEN(C11)>0,"N","") | N11: =IF(ISBLANK(Requerimiento_Cab!J11),"",VLOOKUP(Requerimiento_Cab!J11,Tabla9[#All],2,FALSE)) | O11: =IF(LEN(C11)>0,"TRUJ","") | P11: =IF(LEN(C11)>0,"L","") | Q11: =IF(ISBLANK(Requerimiento_Cab!K11),"",VLOOKUP(Requerimiento_Cab!K11,Tabla10[#All],2,FALSE)) | R11: =IF(LEN(Requerimiento_Cab!L11)>0,Requerimiento_Cab!L11,"") | S11: =IF(LEN(C11)>0,"RV","") | T11: =IF(LEN(C11)>0,"DEMO","") | U11: =IF(LEN(C11)>0,"0","") | V11: =IF(ISBLANK(Requerimiento_Cab!F11),"",VLOOKUP(Requerimiento_Cab!F11,Tabla7[#All],2,FALSE)) | W11: =IF(LEN(C11)>0,"N","") | X11: =IF(ISBLANK(Requerimiento_Cab!M11),"",VLOOKUP(Requerimiento_Cab!M11,Tabla2[#All],2,FALSE)) | Y11: =IF(ISBLANK(Requerimiento_Cab!J11),"",VLOOKUP(Requerimiento_Cab!J11,Tabla9[#All],2,FALSE))
A12: =IF(LEN(Requerimiento_Cab!A12)>0,Requerimiento_Cab!A12,"") | B12: =(IF(LEN(C12)>0,ROW(B12)-1,"")) | C12: =IF(ISBLANK(Requerimiento_Cab!B12),"",VLOOKUP(Requerimiento_Cab!B12,Tabla3[#All],2,FALSE)) | D12: =IF(ISBLANK(Requerimiento_Cab!C12),"",VLOOKUP(Requerimiento_Cab!C12,Tabla4[#All],2,FALSE)) | E12: =IF(ISBLANK(Requerimiento_Cab!D12),"",VLOOKUP(Requerimiento_Cab!D12,Tabla5[#All],2,FALSE)) | F12: =IF(ISBLANK(Requerimiento_Cab!E12),"",VLOOKUP(Requerimiento_Cab!E12,Tabla6[#All],2,FALSE)) | G12: =IF(LEN(C12)>0,"LO","") | H12: =IF(LEN(C12)>0,"0","") | I12: =IF(ISBLANK(Requerimiento_Cab!F12),"",VLOOKUP(Requerimiento_Cab!F12,Tabla7[#All],2,FALSE)) | J12: =IF(LEN(C12)>0,"1","") | K12: =IF(ISBLANK(Requerimiento_Cab!G12),"",VLOOKUP(Requerimiento_Cab!G12,Tabla8[#All],2,FALSE)) | L12: =IF(ISBLANK(Requerimiento_Cab!H12),"",VLOOKUP(Requerimiento_Cab!H12,Tabla1[#All],2,FALSE)) | M12: =IF(LEN(C12)>0,"N","") | N12: =IF(ISBLANK(Requerimiento_Cab!J12),"",VLOOKUP(Requerimiento_Cab!J12,Tabla9[#All],2,FALSE)) | O12: =IF(LEN(C12)>0,"TRUJ","") | P12: =IF(LEN(C12)>0,"L","") | Q12: =IF(ISBLANK(Requerimiento_Cab!K12),"",VLOOKUP(Requerimiento_Cab!K12,Tabla10[#All],2,FALSE)) | R12: =IF(LEN(Requerimiento_Cab!L12)>0,Requerimiento_Cab!L12,"") | S12: =IF(LEN(C12)>0,"RV","") | T12: =IF(LEN(C12)>0,"DEMO","") | U12: =IF(LEN(C12)>0,"0","") | V12: =IF(ISBLANK(Requerimiento_Cab!F12),"",VLOOKUP(Requerimiento_Cab!F12,Tabla7[#All],2,FALSE)) | W12: =IF(LEN(C12)>0,"N","") | X12: =IF(ISBLANK(Requerimiento_Cab!M12),"",VLOOKUP(Requerimiento_Cab!M12,Tabla2[#All],2,FALSE)) | Y12: =IF(ISBLANK(Requerimiento_Cab!J12),"",VLOOKUP(Requerimiento_Cab!J12,Tabla9[#All],2,FALSE))
A13: =IF(LEN(Requerimiento_Cab!A13)>0,Requerimiento_Cab!A13,"") | B13: =(IF(LEN(C13)>0,ROW(B13)-1,"")) | C13: =IF(ISBLANK(Requerimiento_Cab!B13),"",VLOOKUP(Requerimiento_Cab!B13,Tabla3[#All],2,FALSE)) | D13: =IF(ISBLANK(Requerimiento_Cab!C13),"",VLOOKUP(Requerimiento_Cab!C13,Tabla4[#All],2,FALSE)) | E13: =IF(ISBLANK(Requerimiento_Cab!D13),"",VLOOKUP(Requerimiento_Cab!D13,Tabla5[#All],2,FALSE)) | F13: =IF(ISBLANK(Requerimiento_Cab!E13),"",VLOOKUP(Requerimiento_Cab!E13,Tabla6[#All],2,FALSE)) | G13: =IF(LEN(C13)>0,"LO","") | H13: =IF(LEN(C13)>0,"0","") | I13: =IF(ISBLANK(Requerimiento_Cab!F13),"",VLOOKUP(Requerimiento_Cab!F13,Tabla7[#All],2,FALSE)) | J13: =IF(LEN(C13)>0,"1","") | K13: =IF(ISBLANK(Requerimiento_Cab!G13),"",VLOOKUP(Requerimiento_Cab!G13,Tabla8[#All],2,FALSE)) | L13: =IF(ISBLANK(Requerimiento_Cab!H13),"",VLOOKUP(Requerimiento_Cab!H13,Tabla1[#All],2,FALSE)) | M13: =IF(LEN(C13)>0,"N","") | N13: =IF(ISBLANK(Requerimiento_Cab!J13),"",VLOOKUP(Requerimiento_Cab!J13,Tabla9[#All],2,FALSE)) | O13: =IF(LEN(C13)>0,"TRUJ","") | P13: =IF(LEN(C13)>0,"L","") | Q13: =IF(ISBLANK(Requerimiento_Cab!K13),"",VLOOKUP(Requerimiento_Cab!K13,Tabla10[#All],2,FALSE)) | R13: =IF(LEN(Requerimiento_Cab!L13)>0,Requerimiento_Cab!L13,"") | S13: =IF(LEN(C13)>0,"RV","") | T13: =IF(LEN(C13)>0,"DEMO","") | U13: =IF(LEN(C13)>0,"0","") | V13: =IF(ISBLANK(Requerimiento_Cab!F13),"",VLOOKUP(Requerimiento_Cab!F13,Tabla7[#All],2,FALSE)) | W13: =IF(LEN(C13)>0,"N","") | X13: =IF(ISBLANK(Requerimiento_Cab!M13),"",VLOOKUP(Requerimiento_Cab!M13,Tabla2[#All],2,FALSE)) | Y13: =IF(ISBLANK(Requerimiento_Cab!J13),"",VLOOKUP(Requerimiento_Cab!J13,Tabla9[#All],2,FALSE))
A14: =IF(LEN(Requerimiento_Cab!A14)>0,Requerimiento_Cab!A14,"") | B14: =(IF(LEN(C14)>0,ROW(B14)-1,"")) | C14: =IF(ISBLANK(Requerimiento_Cab!B14),"",VLOOKUP(Requerimiento_Cab!B14,Tabla3[#All],2,FALSE)) | D14: =IF(ISBLANK(Requerimiento_Cab!C14),"",VLOOKUP(Requerimiento_Cab!C14,Tabla4[#All],2,FALSE)) | E14: =IF(ISBLANK(Requerimiento_Cab!D14),"",VLOOKUP(Requerimiento_Cab!D14,Tabla5[#All],2,FALSE)) | F14: =IF(ISBLANK(Requerimiento_Cab!E14),"",VLOOKUP(Requerimiento_Cab!E14,Tabla6[#All],2,FALSE)) | G14: =IF(LEN(C14)>0,"LO","") | H14: =IF(LEN(C14)>0,"0","") | I14: =IF(ISBLANK(Requerimiento_Cab!F14),"",VLOOKUP(Requerimiento_Cab!F14,Tabla7[#All],2,FALSE)) | J14: =IF(LEN(C14)>0,"1","") | K14: =IF(ISBLANK(Requerimiento_Cab!G14),"",VLOOKUP(Requerimiento_Cab!G14,Tabla8[#All],2,FALSE)) | L14: =IF(ISBLANK(Requerimiento_Cab!H14),"",VLOOKUP(Requerimiento_Cab!H14,Tabla1[#All],2,FALSE)) | M14: =IF(LEN(C14)>0,"N","") | N14: =IF(ISBLANK(Requerimiento_Cab!J14),"",VLOOKUP(Requerimiento_Cab!J14,Tabla9[#All],2,FALSE)) | O14: =IF(LEN(C14)>0,"TRUJ","") | P14: =IF(LEN(C14)>0,"L","") | Q14: =IF(ISBLANK(Requerimiento_Cab!K14),"",VLOOKUP(Requerimiento_Cab!K14,Tabla10[#All],2,FALSE)) | R14: =IF(LEN(Requerimiento_Cab!L14)>0,Requerimiento_Cab!L14,"") | S14: =IF(LEN(C14)>0,"RV","") | T14: =IF(LEN(C14)>0,"DEMO","") | U14: =IF(LEN(C14)>0,"0","") | V14: =IF(ISBLANK(Requerimiento_Cab!F14),"",VLOOKUP(Requerimiento_Cab!F14,Tabla7[#All],2,FALSE)) | W14: =IF(LEN(C14)>0,"N","") | X14: =IF(ISBLANK(Requerimiento_Cab!M14),"",VLOOKUP(Requerimiento_Cab!M14,Tabla2[#All],2,FALSE)) | Y14: =IF(ISBLANK(Requerimiento_Cab!J14),"",VLOOKUP(Requerimiento_Cab!J14,Tabla9[#All],2,FALSE))
... A800: =IF(LEN(Requerimiento_Cab!A800)>0,Requerimiento_Cab!A800,"") | B800: =(IF(LEN(C800)>0,ROW(B800)-1,"")) | C800: =IF(ISBLANK(Requerimiento_Cab!B800),"",VLOOKUP(Requerimiento_Cab!B800,Tabla3[#All],2,FALSE)) | D800: =IF(ISBLANK(Requerimiento_Cab!C800),"",VLOOKUP(Requerimiento_Cab!C800,Tabla4[#All],2,FALSE)) | E800: =IF(ISBLANK(Requerimiento_Cab!D800),"",VLOOKUP(Requerimiento_Cab!D800,Tabla5[#All],2,FALSE)) | F800: =IF(ISBLANK(Requerimiento_Cab!E800),"",VLOOKUP(Requerimiento_Cab!E800,Tabla6[#All],2,FALSE)) | G800: =IF(LEN(C800)>0,"LO","") | H800: =IF(LEN(C800)>0,"0","") | I800: =IF(ISBLANK(Requerimiento_Cab!F800),"",VLOOKUP(Requerimiento_Cab!F800,Tabla7[#All],2,FALSE)) | J800: =IF(LEN(C800)>0,"1","") | K800: =IF(ISBLANK(Requerimiento_Cab!G800),"",VLOOKUP(Requerimiento_Cab!G800,Tabla8[#All],2,FALSE)) | L800: =IF(ISBLANK(Requerimiento_Cab!H800),"",VLOOKUP(Requerimiento_Cab!H800,Tabla1[#All],2,FALSE)) | M800: =IF(LEN(C800)>0,"N","") | N800: =IF(ISBLANK(Requerimiento_Cab!J800),"",VLOOKUP(Requerimiento_Cab!J800,Tabla9[#All],2,FALSE)) | O800: =IF(LEN(C800)>0,"TRUJ","") | P800: =IF(LEN(C800)>0,"L","") | Q800: =IF(ISBLANK(Requerimiento_Cab!K800),"",VLOOKUP(Requerimiento_Cab!K800,Tabla10[#All],2,FALSE)) | R800: =IF(LEN(Requerimiento_Cab!L800)>0,Requerimiento_Cab!L800,"") | S800: =IF(LEN(C800)>0,"RV","") | T800: =IF(LEN(C800)>0,"DEMO","") | U800: =IF(LEN(C800)>0,"0","") | V800: =IF(ISBLANK(Requerimiento_Cab!F800),"",VLOOKUP(Requerimiento_Cab!F800,Tabla7[#All],2,FALSE)) | W800: =IF(LEN(C800)>0,"N","") | X800: =IF(ISBLANK(Requerimiento_Cab!M800),"",VLOOKUP(Requerimiento_Cab!M800,Tabla2[#All],2,FALSE)) | Y800: =IF(ISBLANK(Requerimiento_Cab!J800),"",VLOOKUP(Requerimiento_Cab!J800,Tabla9[#All],2,FALSE))

Sheet Requerimiento_Det
A1: SecuenciaCabecera | B1: SecuenciaDetalle | C1: CompaniaSocio | D1: Codigo Item | E1: Condicion | F1: Commodity | G1: UnidadCodigo | H1: Descripcion | I1: Dirigido a | J1: CantidadPedido | K1: PrecioUnitario | L1: Comentario | M1: CentroCosto | N1: PLACA | O1: Proyecto | P1: Sucursal
A2: =(IF(LEN(C2)>0,1,"")) -> 1 | B2: =(IF(LEN(C2)>0,ROW(B2)-1,"")) -> 1 | C2: GRUPO TRANSPESA SAC | E2: Nuevo | F2: PEAJES | G2: Unidad | H2: Pacanguilla 287213 TRUJILLO PIURA TRUJILLO | I2: Compras | J2: 1 | L2: Pacanguilla 287213 TRUJILLO PIURA TRUJILLO | M2: Tractos | N2: T8H891 | O2: =IF(ISBLANK(Requerimiento_Det!N2),"",VLOOKUP(Requerimiento_Det!N2,Tabla1[#All],2,FALSE)) -> 1031100265 | P2: Base Trujillo
A3: =(IF(LEN(C3)>0,1,"")) -> 1 | B3: =(IF(LEN(C3)>0,ROW(B3)-1,"")) -> 2 | C3: GRUPO TRANSPESA SAC | E3: Nuevo | F3: PEAJES | G3: Unidad | H3: Chicama 287270 TRUJILLO CHICLAYO TRUJILLO | I3: Compras | J3: 1 | L3: Chicama 287270 TRUJILLO CHICLAYO TRUJILLO | M3: Tractos | N3: T8C806 | O3: =IF(ISBLANK(Requerimiento_Det!N3),"",VLOOKUP(Requerimiento_Det!N3,Tabla1[#All],2,FALSE)) -> 1031100257 | P3: Base Trujillo
A4: =(IF(LEN(C4)>0,1,"")) -> 1 | B4: =(IF(LEN(C4)>0,ROW(B4)-1,"")) -> 3 | C4: GRUPO TRANSPESA SAC | E4: Nuevo | F4: PEAJES | G4: Unidad | H4: Pacanguilla 287269 TRUJILLO CHICLAYO TRUJILLO | I4: Compras | J4: 1 | L4: Pacanguilla 287269 TRUJILLO CHICLAYO TRUJILLO | M4: Tractos | N4: T9G847 | O4: =IF(ISBLANK(Requerimiento_Det!N4),"",VLOOKUP(Requerimiento_Det!N4,Tabla1[#All],2,FALSE)) -> 1031100305 | P4: Base Trujillo
A5: =(IF(LEN(C5)>0,1,"")) -> 1 | B5: =(IF(LEN(C5)>0,ROW(B5)-1,"")) -> 4 | C5: GRUPO TRANSPESA SAC | E5: Nuevo | F5: PEAJES | G5: Unidad | H5: Pacanguilla 287203 TRUJILLO PIURA TRUJILLO | I5: Compras | J5: 1 | L5: Pacanguilla 287203 TRUJILLO PIURA TRUJILLO | M5: Tractos | N5: T4T948 | O5: =IF(ISBLANK(Requerimiento_Det!N5),"",VLOOKUP(Requerimiento_Det!N5,Tabla1[#All],2,FALSE)) -> 1031100125 | P5: Base Trujillo
A6: =(IF(LEN(C6)>0,1,"")) -> 1 | B6: =(IF(LEN(C6)>0,ROW(B6)-1,"")) -> 5 | C6: GRUPO TRANSPESA SAC | E6: Nuevo | F6: PEAJES | G6: Unidad | H6: Pacanguilla 287277 TRUJILLO PIURA TRUJILLO | I6: Compras | J6: 1 | L6: Pacanguilla 287277 TRUJILLO PIURA TRUJILLO | M6: Tractos | N6: TBB942 | O6: =IF(ISBLANK(Requerimiento_Det!N6),"",VLOOKUP(Requerimiento_Det!N6,Tabla1[#All],2,FALSE)) -> 1031100351 | P6: Base Trujillo
A7: =(IF(LEN(C7)>0,1,"")) -> 1 | B7: =(IF(LEN(C7)>0,ROW(B7)-1,"")) -> 6 | C7: GRUPO TRANSPESA SAC | E7: Nuevo | F7: PEAJES | G7: Unidad | H7: Sullana 287628 TALARA CHICLAYO TALARA | I7: Compras | J7: 1 | L7: Sullana 287628 TALARA CHICLAYO TALARA | M7: Tractos | N7: T8Z852 | O7: =IF(ISBLANK(Requerimiento_Det!N7),"",VLOOKUP(Requerimiento_Det!N7,Tabla1[#All],2,FALSE)) -> 1031100294 | P7: Base Trujillo
A8: =(IF(LEN(C8)>0,1,"")) -> 1 | B8: =(IF(LEN(C8)>0,ROW(B8)-1,"")) -> 7 | C8: GRUPO TRANSPESA SAC | E8: Nuevo | F8: PEAJES | G8: Unidad | H8: Chicama 287173 TRUJILLO PIURA TRUJILLO | I8: Compras | J8: 1 | L8: Chicama 287173 TRUJILLO PIURA TRUJILLO | M8: Tractos | N8: TAD844 | O8: =IF(ISBLANK(Requerimiento_Det!N8),"",VLOOKUP(Requerimiento_Det!N8,Tabla1[#All],2,FALSE)) -> 1031100323 | P8: Base Trujillo
A9: =(IF(LEN(C9)>0,1,"")) -> 1 | B9: =(IF(LEN(C9)>0,ROW(B9)-1,"")) -> 8 | C9: GRUPO TRANSPESA SAC | E9: Nuevo | F9: PEAJES | G9: Unidad | H9: Pacanguilla 287268 TRUJILLO CHICLAYO TRUJILLO | I9: Compras | J9: 1 | L9: Pacanguilla 287268 TRUJILLO CHICLAYO TRUJILLO | M9: Tractos | N9: TAD868 | O9: =IF(ISBLANK(Requerimiento_Det!N9),"",VLOOKUP(Requerimiento_Det!N9,Tabla1[#All],2,FALSE)) -> 1031100324 | P9: Base Trujillo
A10: =(IF(LEN(C10)>0,1,"")) -> 1 | B10: =(IF(LEN(C10)>0,ROW(B10)-1,"")) -> 9 | C10: GRUPO TRANSPESA SAC | E10: Nuevo | F10: PEAJES | G10: Unidad | H10: Chicama 287321 TRUJILLO PACASMAYO TRUJILLO | I10: Compras | J10: 1 | L10: Chicama 287321 TRUJILLO PACASMAYO TRUJILLO | M10: Tractos | N10: T9G827 | O10: =IF(ISBLANK(Requerimiento_Det!N10),"",VLOOKUP(Requerimiento_Det!N10,Tabla1[#All],2,FALSE)) -> 1031100300 | P10: Base Trujillo
A11: =(IF(LEN(C11)>0,1,"")) -> 1 | B11: =(IF(LEN(C11)>0,ROW(B11)-1,"")) -> 10 | C11: GRUPO TRANSPESA SAC | E11: Nuevo | F11: PEAJES | G11: Unidad | H11: Mórrope 287276 TRUJILLO PIURA TRUJILLO | I11: Compras | J11: 1 | L11: Mórrope 287276 TRUJILLO PIURA TRUJILLO | M11: Tractos | N11: TBH919 | O11: =IF(ISBLANK(Requerimiento_Det!N11),"",VLOOKUP(Requerimiento_Det!N11,Tabla1[#All],2,FALSE)) -> 1031100363 | P11: Base Trujillo
A12: =(IF(LEN(C12)>0,1,"")) -> 1 | B12: =(IF(LEN(C12)>0,ROW(B12)-1,"")) -> 11 | C12: GRUPO TRANSPESA SAC | E12: Nuevo | F12: PEAJES | G12: Unidad | H12: Sullana 287585 TALARA PIURA TALARA | I12: Compras | J12: 1 | L12: Sullana 287585 TALARA PIURA TALARA | M12: Tractos | N12: T8N850 | O12: =IF(ISBLANK(Requerimiento_Det!N12),"",VLOOKUP(Requerimiento_Det!N12,Tabla1[#All],2,FALSE)) -> 1031100278 | P12: Base Trujillo
A13: =(IF(LEN(C13)>0,1,"")) -> 1 | B13: =(IF(LEN(C13)>0,ROW(B13)-1,"")) -> 12 | C13: GRUPO TRANSPESA SAC | E13: Nuevo | F13: PEAJES | G13: Unidad | H13: Pacanguilla 287202 TRUJILLO PIURA TRUJILLO | I13: Compras | J13: 1 | L13: Pacanguilla 287202 TRUJILLO PIURA TRUJILLO | M13: Tractos | N13: TAD873 | O13: =IF(ISBLANK(Requerimiento_Det!N13),"",VLOOKUP(Requerimiento_Det!N13,Tabla1[#All],2,FALSE)) -> 1031100326 | P13: Base Trujillo
... A543: =(IF(LEN(C543)>0,1,"")) -> 1 | B543: =(IF(LEN(C543)>0,ROW(B543)-1,"")) -> 542 | C543: GRUPO TRANSPESA SAC | E543: Nuevo | F543: PEAJES | G543: Unidad | H543: Pacanguilla 287864 TRUJILLO CHICLAYO TRUJILLO | I543: Compras | J543: 1 | L543: Pacanguilla 287864 TRUJILLO CHICLAYO TRUJILLO | M543: Tractos | N543: ADT925 | O543: =IF(ISBLANK(Requerimiento_Det!N543),"",VLOOKUP(Requerimiento_Det!N543,Tabla1[#All],2,FALSE)) -> 1031100339 | P543: Base Trujillo

Sheet GenerarDataDetalle
A1: SecuenciaCabecera | B1: SecuenciaDetalle | C1: CompaniaSocio | D1: Item | E1: Condicion | F1: Commodity | G1: UnidadCodigo | H1: Descripcion | I1: ComprasAlmacenFlag | J1: RedefinidoFlag | K1: CantidadPedida | L1: CantidadOrdenCompra | M1: CantidadRecibida | N1: PrecioUnitario | O1: PrecioxCantidad | P1: CotizacionSecuencia | Q1: CotizacionCantidad | R1: CotizacionPrecioUnitario | S1: CotizacionPrecioUnitarioconIGV | T1: CotizacionProveedor | U1: CotizacionRegistros | V1: ControlPresupuestalFlag | W1: Comentario | X1: CentroCosto | Y1: Estado | Z1: UltimoUsuario | AA1: IGVExoneradoFlag | AB1: GenerarContratoFlag | AC1: CuentaContable | AD1: Afe | AE1: Sucursal
A2: 1 | B2: =IF(LEN(Requerimiento_Det!B2)>0,Requerimiento_Det!B2,"") -> 1 | C2: =IF(ISBLANK(Requerimiento_Det!C2),"",VLOOKUP(Requerimiento_Det!C2,Tabla3[#All],2,FALSE)) -> 10000000 | D2: =IF(LEN(Requerimiento_Det!D2)>0,Requerimiento_Det!D2,"") | E2: =IF(ISBLANK(Requerimiento_Det!E2),"",VLOOKUP(Requerimiento_Det!E2,Tabla13[#All],2,FALSE)) -> 0 | F2: =IF(ISBLANK(Requerimiento_Det!F2),"",VLOOKUP(Requerimiento_Det!F2,Tabla12[#All],2,FALSE)) -> 2806 | G2: =IF(ISBLANK(Requerimiento_Det!G2),"",VLOOKUP(Requerimiento_Det!G2,Tabla14[#All],2,FALSE)) -> UNI | H2: =IF(LEN(Requerimiento_Det!H2)>0,Requerimiento_Det!H2,"") -> Pacanguilla 287213 TRUJILLO PIURA TRUJILLO | I2: =IF(ISBLANK(Requerimiento_Det!I2),"",VLOOKUP(Requerimiento_Det!I2,Tabla5[#All],2,FALSE)) -> C | J2: =IF(LEN(C2)>0,"N","") -> N | K2: =IF(LEN(Requerimiento_Det!J2)>0,Requerimiento_Det!J2,"") -> 1 | L2: =IF(LEN(C2)>0,"0.00","") -> 0.00 | M2: =IF(LEN(C2)>0,"0.00","") -> 0.00 | N2: =IF(LEN(C2)>0,"0.00","") -> 0.00 | O2: =IF(LEN(N2)>0,K2*N2,"") -> 0 | P2: =IF(LEN(C2)>0,"0","") -> 0 | Q2: =IF(LEN(C2)>0,"0","") -> 0 | R2: =IF(LEN(C2)>0,"0.000000","") -> 0.000000 | S2: =IF(LEN(C2)>0,"0.000000","") -> 0.000000 | T2: =IF(LEN(C2)>0,"0","") -> 0 | U2: =IF(LEN(C2)>0,"0","") -> 0 | V2: =IF(LEN(C2)>0,"S","") -> S | W2: =IF(LEN(Requerimiento_Det!L2)>0,Requerimiento_Det!L2,"") -> Pacanguilla 287213 TRUJILLO PIURA TRUJILLO | X2: =IF(ISBLANK(Requerimiento_Det!M2),"",VLOOKUP(Requerimiento_Det!M2,Tabla8[#All],2,FALSE)) -> 010201 | Y2: =IF(LEN(C2)>0,"PR","") -> PR | Z2: =IF(LEN(C2)>0,"DEMO","") -> DEMO | AA2: =IF(LEN(C2)>0,"N","") -> N | AB2: =IF(LEN(C2)>0,"N","") -> N | AC2: =IF(LEN(C2)>0,"9031501","") -> 9031501 | AD2: =IF(ISBLANK(Requerimiento_Det!N2),"",VLOOKUP(Requerimiento_Det!N2,Tabla1[#All],2,FALSE)) -> 1031100265 | AE2: =IF(ISBLANK(Requerimiento_Det!P2),"",VLOOKUP(Requerimiento_Det!P2,Tabla18[#All],2,FALSE)) -> BTRU
A3: 1 | B3: =IF(LEN(Requerimiento_Det!B3)>0,Requerimiento_Det!B3,"") -> 2 | C3: =IF(ISBLANK(Requerimiento_Det!C3),"",VLOOKUP(Requerimiento_Det!C3,Tabla3[#All],2,FALSE)) -> 10000000 | D3: =IF(LEN(Requerimiento_Det!D3)>0,Requerimiento_Det!D3,"") | E3: =IF(ISBLANK(Requerimiento_Det!E3),"",VLOOKUP(Requerimiento_Det!E3,Tabla13[#All],2,FALSE)) -> 0 | F3: =IF(ISBLANK(Requerimiento_Det!F3),"",VLOOKUP(Requerimiento_Det!F3,Tabla12[#All],2,FALSE)) -> 2806 | G3: =IF(ISBLANK(Requerimiento_Det!G3),"",VLOOKUP(Requerimiento_Det!G3,Tabla14[#All],2,FALSE)) -> UNI | H3: =IF(LEN(Requerimiento_Det!H3)>0,Requerimiento_Det!H3,"") -> Chicama 287270 TRUJILLO CHICLAYO TRUJILLO | I3: =IF(ISBLANK(Requerimiento_Det!I3),"",VLOOKUP(Requerimiento_Det!I3,Tabla5[#All],2,FALSE)) -> C | J3: =IF(LEN(C3)>0,"N","") -> N | K3: =IF(LEN(Requerimiento_Det!J3)>0,Requerimiento_Det!J3,"") -> 1 | L3: =IF(LEN(C3)>0,"0.00","") -> 0.00 | M3: =IF(LEN(C3)>0,"0.00","") -> 0.00 | N3: =IF(LEN(C3)>0,"0.00","") -> 0.00 | O3: =IF(LEN(N3)>0,K3*N3,"") -> 0 | P3: =IF(LEN(C3)>0,"0","") -> 0 | Q3: =IF(LEN(C3)>0,"0","") -> 0 | R3: =IF(LEN(C3)>0,"0.000000","") -> 0.000000 | S3: =IF(LEN(C3)>0,"0.000000","") -> 0.000000 | T3: =IF(LEN(C3)>0,"0","") -> 0 | U3: =IF(LEN(C3)>0,"0","") -> 0 | V3: =IF(LEN(C3)>0,"S","") -> S | W3: =IF(LEN(Requerimiento_Det!L3)>0,Requerimiento_Det!L3,"") -> Chicama 287270 TRUJILLO CHICLAYO TRUJILLO | X3: =IF(ISBLANK(Requerimiento_Det!M3),"",VLOOKUP(Requerimiento_Det!M3,Tabla8[#All],2,FALSE)) -> 010201 | Y3: =IF(LEN(C3)>0,"PR","") -> PR | Z3: =IF(LEN(C3)>0,"DEMO","") -> DEMO | AA3: =IF(LEN(C3)>0,"N","") -> N | AB3: =IF(LEN(C3)>0,"N","") -> N | AC3: =IF(LEN(C3)>0,"9031501","") -> 9031501 | AD3: =IF(ISBLANK(Requerimiento_Det!N3),"",VLOOKUP(Requerimiento_Det!N3,Tabla1[#All],2,FALSE)) -> 1031100257 | AE3: =IF(ISBLANK(Requerimiento_Det!P3),"",VLOOKUP(Requerimiento_Det!P3,Tabla18[#All],2,FALSE)) -> BTRU
A4: 1 | B4: =IF(LEN(Requerimiento_Det!B4)>0,Requerimiento_Det!B4,"") -> 3 | C4: =IF(ISBLANK(Requerimiento_Det!C4),"",VLOOKUP(Requerimiento_Det!C4,Tabla3[#All],2,FALSE)) -> 10000000 | D4: =IF(LEN(Requerimiento_Det!D4)>0,Requerimiento_Det!D4,"") | E4: =IF(ISBLANK(Requerimiento_Det!E4),"",VLOOKUP(Requerimiento_Det!E4,Tabla13[#All],2,FALSE)) -> 0 | F4: =IF(ISBLANK(Requerimiento_Det!F4),"",VLOOKUP(Requerimiento_Det!F4,Tabla12[#All],2,FALSE)) -> 2806 | G4: =IF(ISBLANK(Requerimiento_Det!G4),"",VLOOKUP(Requerimiento_Det!G4,Tabla14[#All],2,FALSE)) -> UNI | H4: =IF(LEN(Requerimiento_Det!H4)>0,Requerimiento_Det!H4,"") -> Pacanguilla 287269 TRUJILLO CHICLAYO TRUJILLO | I4: =IF(ISBLANK(Requerimiento_Det!I4),"",VLOOKUP(Requerimiento_Det!I4,Tabla5[#All],2,FALSE)) -> C | J4: =IF(LEN(C4)>0,"N","") -> N | K4: =IF(LEN(Requerimiento_Det!J4)>0,Requerimiento_Det!J4,"") -> 1 | L4: =IF(LEN(C4)>0,"0.00","") -> 0.00 | M4: =IF(LEN(C4)>0,"0.00","") -> 0.00 | N4: =IF(LEN(C4)>0,"0.00","") -> 0.00 | O4: =IF(LEN(N4)>0,K4*N4,"") -> 0 | P4: =IF(LEN(C4)>0,"0","") -> 0 | Q4: =IF(LEN(C4)>0,"0","") -> 0 | R4: =IF(LEN(C4)>0,"0.000000","") -> 0.000000 | S4: =IF(LEN(C4)>0,"0.000000","") -> 0.000000 | T4: =IF(LEN(C4)>0,"0","") -> 0 | U4: =IF(LEN(C4)>0,"0","") -> 0 | V4: =IF(LEN(C4)>0,"S","") -> S | W4: =IF(LEN(Requerimiento_Det!L4)>0,Requerimiento_Det!L4,"") -> Pacanguilla 287269 TRUJILLO CHICLAYO TRUJILLO | X4: =IF(ISBLANK(Requerimiento_Det!M4),"",VLOOKUP(Requerimiento_Det!M4,Tabla8[#All],2,FALSE)) -> 010201 | Y4: =IF(LEN(C4)>0,"PR","") -> PR | Z4: =IF(LEN(C4)>0,"DEMO","") -> DEMO | AA4: =IF(LEN(C4)>0,"N","") -> N | AB4: =IF(LEN(C4)>0,"N","") -> N | AC4: =IF(LEN(C4)>0,"9031501","") -> 9031501 | AD4: =IF(ISBLANK(Requerimiento_Det!N4),"",VLOOKUP(Requerimiento_Det!N4,Tabla1[#All],2,FALSE)) -> 1031100305 | AE4: =IF(ISBLANK(Requerimiento_Det!P4),"",VLOOKUP(Requerimiento_Det!P4,Tabla18[#All],2,FALSE)) -> BTRU
A5: 1 | B5: =IF(LEN(Requerimiento_Det!B5)>0,Requerimiento_Det!B5,"") -> 4 | C5: =IF(ISBLANK(Requerimiento_Det!C5),"",VLOOKUP(Requerimiento_Det!C5,Tabla3[#All],2,FALSE)) -> 10000000 | D5: =IF(LEN(Requerimiento_Det!D5)>0,Requerimiento_Det!D5,"") | E5: =IF(ISBLANK(Requerimiento_Det!E5),"",VLOOKUP(Requerimiento_Det!E5,Tabla13[#All],2,FALSE)) -> 0 | F5: =IF(ISBLANK(Requerimiento_Det!F5),"",VLOOKUP(Requerimiento_Det!F5,Tabla12[#All],2,FALSE)) -> 2806 | G5: =IF(ISBLANK(Requerimiento_Det!G5),"",VLOOKUP(Requerimiento_Det!G5,Tabla14[#All],2,FALSE)) -> UNI | H5: =IF(LEN(Requerimiento_Det!H5)>0,Requerimiento_Det!H5,"") -> Pacanguilla 287203 TRUJILLO PIURA TRUJILLO | I5: =IF(ISBLANK(Requerimiento_Det!I5),"",VLOOKUP(Requerimiento_Det!I5,Tabla5[#All],2,FALSE)) -> C | J5: =IF(LEN(C5)>0,"N","") -> N | K5: =IF(LEN(Requerimiento_Det!J5)>0,Requerimiento_Det!J5,"") -> 1 | L5: =IF(LEN(C5)>0,"0.00","") -> 0.00 | M5: =IF(LEN(C5)>0,"0.00","") -> 0.00 | N5: =IF(LEN(C5)>0,"0.00","") -> 0.00 | O5: =IF(LEN(N5)>0,K5*N5,"") -> 0 | P5: =IF(LEN(C5)>0,"0","") -> 0 | Q5: =IF(LEN(C5)>0,"0","") -> 0 | R5: =IF(LEN(C5)>0,"0.000000","") -> 0.000000 | S5: =IF(LEN(C5)>0,"0.000000","") -> 0.000000 | T5: =IF(LEN(C5)>0,"0","") -> 0 | U5: =IF(LEN(C5)>0,"0","") -> 0 | V5: =IF(LEN(C5)>0,"S","") -> S | W5: =IF(LEN(Requerimiento_Det!L5)>0,Requerimiento_Det!L5,"") -> Pacanguilla 287203 TRUJILLO PIURA TRUJILLO | X5: =IF(ISBLANK(Requerimiento_Det!M5),"",VLOOKUP(Requerimiento_Det!M5,Tabla8[#All],2,FALSE)) -> 010201 | Y5: =IF(LEN(C5)>0,"PR","") -> PR | Z5: =IF(LEN(C5)>0,"DEMO","") -> DEMO | AA5: =IF(LEN(C5)>0,"N","") -> N | AB5: =IF(LEN(C5)>0,"N","") -> N | AC5: =IF(LEN(C5)>0,"9031501","") -> 9031501 | AD5: =IF(ISBLANK(Requerimiento_Det!N5),"",VLOOKUP(Requerimiento_Det!N5,Tabla1[#All],2,FALSE)) -> 1031100125 | AE5: =IF(ISBLANK(Requerimiento_Det!P5),"",VLOOKUP(Requerimiento_Det!P5,Tabla18[#All],2,FALSE)) -> BTRU
A6: 1 | B6: =IF(LEN(Requerimiento_Det!B6)>0,Requerimiento_Det!B6,"") -> 5 | C6: =IF(ISBLANK(Requerimiento_Det!C6),"",VLOOKUP(Requerimiento_Det!C6,Tabla3[#All],2,FALSE)) -> 10000000 | D6: =IF(LEN(Requerimiento_Det!D6)>0,Requerimiento_Det!D6,"") | E6: =IF(ISBLANK(Requerimiento_Det!E6),"",VLOOKUP(Requerimiento_Det!E6,Tabla13[#All],2,FALSE)) -> 0 | F6: =IF(ISBLANK(Requerimiento_Det!F6),"",VLOOKUP(Requerimiento_Det!F6,Tabla12[#All],2,FALSE)) -> 2806 | G6: =IF(ISBLANK(Requerimiento_Det!G6),"",VLOOKUP(Requerimiento_Det!G6,Tabla14[#All],2,FALSE)) -> UNI | H6: =IF(LEN(Requerimiento_Det!H6)>0,Requerimiento_Det!H6,"") -> Pacanguilla 287277 TRUJILLO PIURA TRUJILLO | I6: =IF(ISBLANK(Requerimiento_Det!I6),"",VLOOKUP(Requerimiento_Det!I6,Tabla5[#All],2,FALSE)) -> C | J6: =IF(LEN(C6)>0,"N","") -> N | K6: =IF(LEN(Requerimiento_Det!J6)>0,Requerimiento_Det!J6,"") -> 1 | L6: =IF(LEN(C6)>0,"0.00","") -> 0.00 | M6: =IF(LEN(C6)>0,"0.00","") -> 0.00 | N6: =IF(LEN(C6)>0,"0.00","") -> 0.00 | O6: =IF(LEN(N6)>0,K6*N6,"") -> 0 | P6: =IF(LEN(C6)>0,"0","") -> 0 | Q6: =IF(LEN(C6)>0,"0","") -> 0 | R6: =IF(LEN(C6)>0,"0.000000","") -> 0.000000 | S6: =IF(LEN(C6)>0,"0.000000","") -> 0.000000 | T6: =IF(LEN(C6)>0,"0","") -> 0 | U6: =IF(LEN(C6)>0,"0","") -> 0 | V6: =IF(LEN(C6)>0,"S","") -> S | W6: =IF(LEN(Requerimiento_Det!L6)>0,Requerimiento_Det!L6,"") -> Pacanguilla 287277 TRUJILLO PIURA TRUJILLO | X6: =IF(ISBLANK(Requerimiento_Det!M6),"",VLOOKUP(Requerimiento_Det!M6,Tabla8[#All],2,FALSE)) -> 010201 | Y6: =IF(LEN(C6)>0,"PR","") -> PR | Z6: =IF(LEN(C6)>0,"DEMO","") -> DEMO | AA6: =IF(LEN(C6)>0,"N","") -> N | AB6: =IF(LEN(C6)>0,"N","") -> N | AC6: =IF(LEN(C6)>0,"9031501","") -> 9031501 | AD6: =IF(ISBLANK(Requerimiento_Det!N6),"",VLOOKUP(Requerimiento_Det!N6,Tabla1[#All],2,FALSE)) -> 1031100351 | AE6: =IF(ISBLANK(Requerimiento_Det!P6),"",VLOOKUP(Requerimiento_Det!P6,Tabla18[#All],2,FALSE)) -> BTRU
A7: 1 | B7: =IF(LEN(Requerimiento_Det!B7)>0,Requerimiento_Det!B7,"") -> 6 | C7: =IF(ISBLANK(Requerimiento_Det!C7),"",VLOOKUP(Requerimiento_Det!C7,Tabla3[#All],2,FALSE)) -> 10000000 | D7: =IF(LEN(Requerimiento_Det!D7)>0,Requerimiento_Det!D7,"") | E7: =IF(ISBLANK(Requerimiento_Det!E7),"",VLOOKUP(Requerimiento_Det!E7,Tabla13[#All],2,FALSE)) -> 0 | F7: =IF(ISBLANK(Requerimiento_Det!F7),"",VLOOKUP(Requerimiento_Det!F7,Tabla12[#All],2,FALSE)) -> 2806 | G7: =IF(ISBLANK(Requerimiento_Det!G7),"",VLOOKUP(Requerimiento_Det!G7,Tabla14[#All],2,FALSE)) -> UNI | H7: =IF(LEN(Requerimiento_Det!H7)>0,Requerimiento_Det!H7,"") -> Sullana 287628 TALARA CHICLAYO TALARA | I7: =IF(ISBLANK(Requerimiento_Det!I7),"",VLOOKUP(Requerimiento_Det!I7,Tabla5[#All],2,FALSE)) -> C | J7: =IF(LEN(C7)>0,"N","") -> N | K7: =IF(LEN(Requerimiento_Det!J7)>0,Requerimiento_Det!J7,"") -> 1 | L7: =IF(LEN(C7)>0,"0.00","") -> 0.00 | M7: =IF(LEN(C7)>0,"0.00","") -> 0.00 | N7: =IF(LEN(C7)>0,"0.00","") -> 0.00 | O7: =IF(LEN(N7)>0,K7*N7,"") -> 0 | P7: =IF(LEN(C7)>0,"0","") -> 0 | Q7: =IF(LEN(C7)>0,"0","") -> 0 | R7: =IF(LEN(C7)>0,"0.000000","") -> 0.000000 | S7: =IF(LEN(C7)>0,"0.000000","") -> 0.000000 | T7: =IF(LEN(C7)>0,"0","") -> 0 | U7: =IF(LEN(C7)>0,"0","") -> 0 | V7: =IF(LEN(C7)>0,"S","") -> S | W7: =IF(LEN(Requerimiento_Det!L7)>0,Requerimiento_Det!L7,"") -> Sullana 287628 TALARA CHICLAYO TALARA | X7: =IF(ISBLANK(Requerimiento_Det!M7),"",VLOOKUP(Requerimiento_Det!M7,Tabla8[#All],2,FALSE)) -> 010201 | Y7: =IF(LEN(C7)>0,"PR","") -> PR | Z7: =IF(LEN(C7)>0,"DEMO","") -> DEMO | AA7: =IF(LEN(C7)>0,"N","") -> N | AB7: =IF(LEN(C7)>0,"N","") -> N | AC7: =IF(LEN(C7)>0,"9031501","") -> 9031501 | AD7: =IF(ISBLANK(Requerimiento_Det!N7),"",VLOOKUP(Requerimiento_Det!N7,Tabla1[#All],2,FALSE)) -> 1031100294 | AE7: =IF(ISBLANK(Requerimiento_Det!P7),"",VLOOKUP(Requerimiento_Det!P7,Tabla18[#All],2,FALSE)) -> BTRU
A8: 1 | B8: =IF(LEN(Requerimiento_Det!B8)>0,Requerimiento_Det!B8,"") -> 7 | C8: =IF(ISBLANK(Requerimiento_Det!C8),"",VLOOKUP(Requerimiento_Det!C8,Tabla3[#All],2,FALSE)) -> 10000000 | D8: =IF(LEN(Requerimiento_Det!D8)>0,Requerimiento_Det!D8,"") | E8: =IF(ISBLANK(Requerimiento_Det!E8),"",VLOOKUP(Requerimiento_Det!E8,Tabla13[#All],2,FALSE)) -> 0 | F8: =IF(ISBLANK(Requerimiento_Det!F8),"",VLOOKUP(Requerimiento_Det!F8,Tabla12[#All],2,FALSE)) -> 2806 | G8: =IF(ISBLANK(Requerimiento_Det!G8),"",VLOOKUP(Requerimiento_Det!G8,Tabla14[#All],2,FALSE)) -> UNI | H8: =IF(LEN(Requerimiento_Det!H8)>0,Requerimiento_Det!H8,"") -> Chicama 287173 TRUJILLO PIURA TRUJILLO | I8: =IF(ISBLANK(Requerimiento_Det!I8),"",VLOOKUP(Requerimiento_Det!I8,Tabla5[#All],2,FALSE)) -> C | J8: =IF(LEN(C8)>0,"N","") -> N | K8: =IF(LEN(Requerimiento_Det!J8)>0,Requerimiento_Det!J8,"") -> 1 | L8: =IF(LEN(C8)>0,"0.00","") -> 0.00 | M8: =IF(LEN(C8)>0,"0.00","") -> 0.00 | N8: =IF(LEN(C8)>0,"0.00","") -> 0.00 | O8: =IF(LEN(N8)>0,K8*N8,"") -> 0 | P8: =IF(LEN(C8)>0,"0","") -> 0 | Q8: =IF(LEN(C8)>0,"0","") -> 0 | R8: =IF(LEN(C8)>0,"0.000000","") -> 0.000000 | S8: =IF(LEN(C8)>0,"0.000000","") -> 0.000000 | T8: =IF(LEN(C8)>0,"0","") -> 0 | U8: =IF(LEN(C8)>0,"0","") -> 0 | V8: =IF(LEN(C8)>0,"S","") -> S | W8: =IF(LEN(Requerimiento_Det!L8)>0,Requerimiento_Det!L8,"") -> Chicama 287173 TRUJILLO PIURA TRUJILLO | X8: =IF(ISBLANK(Requerimiento_Det!M8),"",VLOOKUP(Requerimiento_Det!M8,Tabla8[#All],2,FALSE)) -> 010201 | Y8: =IF(LEN(C8)>0,"PR","") -> PR | Z8: =IF(LEN(C8)>0,"DEMO","") -> DEMO | AA8: =IF(LEN(C8)>0,"N","") -> N | AB8: =IF(LEN(C8)>0,"N","") -> N | AC8: =IF(LEN(C8)>0,"9031501","") -> 9031501 | AD8: =IF(ISBLANK(Requerimiento_Det!N8),"",VLOOKUP(Requerimiento_Det!N8,Tabla1[#All],2,FALSE)) -> 1031100323 | AE8: =IF(ISBLANK(Requerimiento_Det!P8),"",VLOOKUP(Requerimiento_Det!P8,Tabla18[#All],2,FALSE)) -> BTRU
A9: 1 | B9: =IF(LEN(Requerimiento_Det!B9)>0,Requerimiento_Det!B9,"") -> 8 | C9: =IF(ISBLANK(Requerimiento_Det!C9),"",VLOOKUP(Requerimiento_Det!C9,Tabla3[#All],2,FALSE)) -> 10000000 | D9: =IF(LEN(Requerimiento_Det!D9)>0,Requerimiento_Det!D9,"") | E9: =IF(ISBLANK(Requerimiento_Det!E9),"",VLOOKUP(Requerimiento_Det!E9,Tabla13[#All],2,FALSE)) -> 0 | F9: =IF(ISBLANK(Requerimiento_Det!F9),"",VLOOKUP(Requerimiento_Det!F9,Tabla12[#All],2,FALSE)) -> 2806 | G9: =IF(ISBLANK(Requerimiento_Det!G9),"",VLOOKUP(Requerimiento_Det!G9,Tabla14[#All],2,FALSE)) -> UNI | H9: =IF(LEN(Requerimiento_Det!H9)>0,Requerimiento_Det!H9,"") -> Pacanguilla 287268 TRUJILLO CHICLAYO TRUJILLO | I9: =IF(ISBLANK(Requerimiento_Det!I9),"",VLOOKUP(Requerimiento_Det!I9,Tabla5[#All],2,FALSE)) -> C | J9: =IF(LEN(C9)>0,"N","") -> N | K9: =IF(LEN(Requerimiento_Det!J9)>0,Requerimiento_Det!J9,"") -> 1 | L9: =IF(LEN(C9)>0,"0.00","") -> 0.00 | M9: =IF(LEN(C9)>0,"0.00","") -> 0.00 | N9: =IF(LEN(C9)>0,"0.00","") -> 0.00 | O9: =IF(LEN(N9)>0,K9*N9,"") -> 0 | P9: =IF(LEN(C9)>0,"0","") -> 0 | Q9: =IF(LEN(C9)>0,"0","") -> 0 | R9: =IF(LEN(C9)>0,"0.000000","") -> 0.000000 | S9: =IF(LEN(C9)>0,"0.000000","") -> 0.000000 | T9: =IF(LEN(C9)>0,"0","") -> 0 | U9: =IF(LEN(C9)>0,"0","") -> 0 | V9: =IF(LEN(C9)>0,"S","") -> S | W9: =IF(LEN(Requerimiento_Det!L9)>0,Requerimiento_Det!L9,"") -> Pacanguilla 287268 TRUJILLO CHICLAYO TRUJILLO | X9: =IF(ISBLANK(Requerimiento_Det!M9),"",VLOOKUP(Requerimiento_Det!M9,Tabla8[#All],2,FALSE)) -> 010201 | Y9: =IF(LEN(C9)>0,"PR","") -> PR | Z9: =IF(LEN(C9)>0,"DEMO","") -> DEMO | AA9: =IF(LEN(C9)>0,"N","") -> N | AB9: =IF(LEN(C9)>0,"N","") -> N | AC9: =IF(LEN(C9)>0,"9031501","") -> 9031501 | AD9: =IF(ISBLANK(Requerimiento_Det!N9),"",VLOOKUP(Requerimiento_Det!N9,Tabla1[#All],2,FALSE)) -> 1031100324 | AE9: =IF(ISBLANK(Requerimiento_Det!P9),"",VLOOKUP(Requerimiento_Det!P9,Tabla18[#All],2,FALSE)) -> BTRU
A10: 1 | B10: =IF(LEN(Requerimiento_Det!B10)>0,Requerimiento_Det!B10,"") -> 9 | C10: =IF(ISBLANK(Requerimiento_Det!C10),"",VLOOKUP(Requerimiento_Det!C10,Tabla3[#All],2,FALSE)) -> 10000000 | D10: =IF(LEN(Requerimiento_Det!D10)>0,Requerimiento_Det!D10,"") | E10: =IF(ISBLANK(Requerimiento_Det!E10),"",VLOOKUP(Requerimiento_Det!E10,Tabla13[#All],2,FALSE)) -> 0 | F10: =IF(ISBLANK(Requerimiento_Det!F10),"",VLOOKUP(Requerimiento_Det!F10,Tabla12[#All],2,FALSE)) -> 2806 | G10: =IF(ISBLANK(Requerimiento_Det!G10),"",VLOOKUP(Requerimiento_Det!G10,Tabla14[#All],2,FALSE)) -> UNI | H10: =IF(LEN(Requerimiento_Det!H10)>0,Requerimiento_Det!H10,"") -> Chicama 287321 TRUJILLO PACASMAYO TRUJILLO | I10: =IF(ISBLANK(Requerimiento_Det!I10),"",VLOOKUP(Requerimiento_Det!I10,Tabla5[#All],2,FALSE)) -> C | J10: =IF(LEN(C10)>0,"N","") -> N | K10: =IF(LEN(Requerimiento_Det!J10)>0,Requerimiento_Det!J10,"") -> 1 | L10: =IF(LEN(C10)>0,"0.00","") -> 0.00 | M10: =IF(LEN(C10)>0,"0.00","") -> 0.00 | N10: =IF(LEN(C10)>0,"0.00","") -> 0.00 | O10: =IF(LEN(N10)>0,K10*N10,"") -> 0 | P10: =IF(LEN(C10)>0,"0","") -> 0 | Q10: =IF(LEN(C10)>0,"0","") -> 0 | R10: =IF(LEN(C10)>0,"0.000000","") -> 0.000000 | S10: =IF(LEN(C10)>0,"0.000000","") -> 0.000000 | T10: =IF(LEN(C10)>0,"0","") -> 0 | U10: =IF(LEN(C10)>0,"0","") -> 0 | V10: =IF(LEN(C10)>0,"S","") -> S | W10: =IF(LEN(Requerimiento_Det!L10)>0,Requerimiento_Det!L10,"") -> Chicama 287321 TRUJILLO PACASMAYO TRUJILLO | X10: =IF(ISBLANK(Requerimiento_Det!M10),"",VLOOKUP(Requerimiento_Det!M10,Tabla8[#All],2,FALSE)) -> 010201 | Y10: =IF(LEN(C10)>0,"PR","") -> PR | Z10: =IF(LEN(C10)>0,"DEMO","") -> DEMO | AA10: =IF(LEN(C10)>0,"N","") -> N | AB10: =IF(LEN(C10)>0,"N","") -> N | AC10: =IF(LEN(C10)>0,"9031501","") -> 9031501 | AD10: =IF(ISBLANK(Requerimiento_Det!N10),"",VLOOKUP(Requerimiento_Det!N10,Tabla1[#All],2,FALSE)) -> 1031100300 | AE10: =IF(ISBLANK(Requerimiento_Det!P10),"",VLOOKUP(Requerimiento_Det!P10,Tabla18[#All],2,FALSE)) -> BTRU
A11: 1 | B11: =IF(LEN(Requerimiento_Det!B11)>0,Requerimiento_Det!B11,"") -> 10 | C11: =IF(ISBLANK(Requerimiento_Det!C11),"",VLOOKUP(Requerimiento_Det!C11,Tabla3[#All],2,FALSE)) -> 10000000 | D11: =IF(LEN(Requerimiento_Det!D11)>0,Requerimiento_Det!D11,"") | E11: =IF(ISBLANK(Requerimiento_Det!E11),"",VLOOKUP(Requerimiento_Det!E11,Tabla13[#All],2,FALSE)) -> 0 | F11: =IF(ISBLANK(Requerimiento_Det!F11),"",VLOOKUP(Requerimiento_Det!F11,Tabla12[#All],2,FALSE)) -> 2806 | G11: =IF(ISBLANK(Requerimiento_Det!G11),"",VLOOKUP(Requerimiento_Det!G11,Tabla14[#All],2,FALSE)) -> UNI | H11: =IF(LEN(Requerimiento_Det!H11)>0,Requerimiento_Det!H11,"") -> Mórrope 287276 TRUJILLO PIURA TRUJILLO | I11: =IF(ISBLANK(Requerimiento_Det!I11),"",VLOOKUP(Requerimiento_Det!I11,Tabla5[#All],2,FALSE)) -> C | J11: =IF(LEN(C11)>0,"N","") -> N | K11: =IF(LEN(Requerimiento_Det!J11)>0,Requerimiento_Det!J11,"") -> 1 | L11: =IF(LEN(C11)>0,"0.00","") -> 0.00 | M11: =IF(LEN(C11)>0,"0.00","") -> 0.00 | N11: =IF(LEN(C11)>0,"0.00","") -> 0.00 | O11: =IF(LEN(N11)>0,K11*N11,"") -> 0 | P11: =IF(LEN(C11)>0,"0","") -> 0 | Q11: =IF(LEN(C11)>0,"0","") -> 0 | R11: =IF(LEN(C11)>0,"0.000000","") -> 0.000000 | S11: =IF(LEN(C11)>0,"0.000000","") -> 0.000000 | T11: =IF(LEN(C11)>0,"0","") -> 0 | U11: =IF(LEN(C11)>0,"0","") -> 0 | V11: =IF(LEN(C11)>0,"S","") -> S | W11: =IF(LEN(Requerimiento_Det!L11)>0,Requerimiento_Det!L11,"") -> Mórrope 287276 TRUJILLO PIURA TRUJILLO | X11: =IF(ISBLANK(Requerimiento_Det!M11),"",VLOOKUP(Requerimiento_Det!M11,Tabla8[#All],2,FALSE)) -> 010201 | Y11: =IF(LEN(C11)>0,"PR","") -> PR | Z11: =IF(LEN(C11)>0,"DEMO","") -> DEMO | AA11: =IF(LEN(C11)>0,"N","") -> N | AB11: =IF(LEN(C11)>0,"N","") -> N | AC11: =IF(LEN(C11)>0,"9031501","") -> 9031501 | AD11: =IF(ISBLANK(Requerimiento_Det!N11),"",VLOOKUP(Requerimiento_Det!N11,Tabla1[#All],2,FALSE)) -> 1031100363 | AE11: =IF(ISBLANK(Requerimiento_Det!P11),"",VLOOKUP(Requerimiento_Det!P11,Tabla18[#All],2,FALSE)) -> BTRU
A12: 1 | B12: =IF(LEN(Requerimiento_Det!B12)>0,Requerimiento_Det!B12,"") -> 11 | C12: =IF(ISBLANK(Requerimiento_Det!C12),"",VLOOKUP(Requerimiento_Det!C12,Tabla3[#All],2,FALSE)) -> 10000000 | D12: =IF(LEN(Requerimiento_Det!D12)>0,Requerimiento_Det!D12,"") | E12: =IF(ISBLANK(Requerimiento_Det!E12),"",VLOOKUP(Requerimiento_Det!E12,Tabla13[#All],2,FALSE)) -> 0 | F12: =IF(ISBLANK(Requerimiento_Det!F12),"",VLOOKUP(Requerimiento_Det!F12,Tabla12[#All],2,FALSE)) -> 2806 | G12: =IF(ISBLANK(Requerimiento_Det!G12),"",VLOOKUP(Requerimiento_Det!G12,Tabla14[#All],2,FALSE)) -> UNI | H12: =IF(LEN(Requerimiento_Det!H12)>0,Requerimiento_Det!H12,"") -> Sullana 287585 TALARA PIURA TALARA | I12: =IF(ISBLANK(Requerimiento_Det!I12),"",VLOOKUP(Requerimiento_Det!I12,Tabla5[#All],2,FALSE)) -> C | J12: =IF(LEN(C12)>0,"N","") -> N | K12: =IF(LEN(Requerimiento_Det!J12)>0,Requerimiento_Det!J12,"") -> 1 | L12: =IF(LEN(C12)>0,"0.00","") -> 0.00 | M12: =IF(LEN(C12)>0,"0.00","") -> 0.00 | N12: =IF(LEN(C12)>0,"0.00","") -> 0.00 | O12: =IF(LEN(N12)>0,K12*N12,"") -> 0 | P12: =IF(LEN(C12)>0,"0","") -> 0 | Q12: =IF(LEN(C12)>0,"0","") -> 0 | R12: =IF(LEN(C12)>0,"0.000000","") -> 0.000000 | S12: =IF(LEN(C12)>0,"0.000000","") -> 0.000000 | T12: =IF(LEN(C12)>0,"0","") -> 0 | U12: =IF(LEN(C12)>0,"0","") -> 0 | V12: =IF(LEN(C12)>0,"S","") -> S | W12: =IF(LEN(Requerimiento_Det!L12)>0,Requerimiento_Det!L12,"") -> Sullana 287585 TALARA PIURA TALARA | X12: =IF(ISBLANK(Requerimiento_Det!M12),"",VLOOKUP(Requerimiento_Det!M12,Tabla8[#All],2,FALSE)) -> 010201 | Y12: =IF(LEN(C12)>0,"PR","") -> PR | Z12: =IF(LEN(C12)>0,"DEMO","") -> DEMO | AA12: =IF(LEN(C12)>0,"N","") -> N | AB12: =IF(LEN(C12)>0,"N","") -> N | AC12: =IF(LEN(C12)>0,"9031501","") -> 9031501 | AD12: =IF(ISBLANK(Requerimiento_Det!N12),"",VLOOKUP(Requerimiento_Det!N12,Tabla1[#All],2,FALSE)) -> 1031100278 | AE12: =IF(ISBLANK(Requerimiento_Det!P12),"",VLOOKUP(Requerimiento_Det!P12,Tabla18[#All],2,FALSE)) -> BTRU
A13: 1 | B13: =IF(LEN(Requerimiento_Det!B13)>0,Requerimiento_Det!B13,"") -> 12 | C13: =IF(ISBLANK(Requerimiento_Det!C13),"",VLOOKUP(Requerimiento_Det!C13,Tabla3[#All],2,FALSE)) -> 10000000 | D13: =IF(LEN(Requerimiento_Det!D13)>0,Requerimiento_Det!D13,"") | E13: =IF(ISBLANK(Requerimiento_Det!E13),"",VLOOKUP(Requerimiento_Det!E13,Tabla13[#All],2,FALSE)) -> 0 | F13: =IF(ISBLANK(Requerimiento_Det!F13),"",VLOOKUP(Requerimiento_Det!F13,Tabla12[#All],2,FALSE)) -> 2806 | G13: =IF(ISBLANK(Requerimiento_Det!G13),"",VLOOKUP(Requerimiento_Det!G13,Tabla14[#All],2,FALSE)) -> UNI | H13: =IF(LEN(Requerimiento_Det!H13)>0,Requerimiento_Det!H13,"") -> Pacanguilla 287202 TRUJILLO PIURA TRUJILLO | I13: =IF(ISBLANK(Requerimiento_Det!I13),"",VLOOKUP(Requerimiento_Det!I13,Tabla5[#All],2,FALSE)) -> C | J13: =IF(LEN(C13)>0,"N","") -> N | K13: =IF(LEN(Requerimiento_Det!J13)>0,Requerimiento_Det!J13,"") -> 1 | L13: =IF(LEN(C13)>0,"0.00","") -> 0.00 | M13: =IF(LEN(C13)>0,"0.00","") -> 0.00 | N13: =IF(LEN(C13)>0,"0.00","") -> 0.00 | O13: =IF(LEN(N13)>0,K13*N13,"") -> 0 | P13: =IF(LEN(C13)>0,"0","") -> 0 | Q13: =IF(LEN(C13)>0,"0","") -> 0 | R13: =IF(LEN(C13)>0,"0.000000","") -> 0.000000 | S13: =IF(LEN(C13)>0,"0.000000","") -> 0.000000 | T13: =IF(LEN(C13)>0,"0","") -> 0 | U13: =IF(LEN(C13)>0,"0","") -> 0 | V13: =IF(LEN(C13)>0,"S","") -> S | W13: =IF(LEN(Requerimiento_Det!L13)>0,Requerimiento_Det!L13,"") -> Pacanguilla 287202 TRUJILLO PIURA TRUJILLO | X13: =IF(ISBLANK(Requerimiento_Det!M13),"",VLOOKUP(Requerimiento_Det!M13,Tabla8[#All],2,FALSE)) -> 010201 | Y13: =IF(LEN(C13)>0,"PR","") -> PR | Z13: =IF(LEN(C13)>0,"DEMO","") -> DEMO | AA13: =IF(LEN(C13)>0,"N","") -> N | AB13: =IF(LEN(C13)>0,"N","") -> N | AC13: =IF(LEN(C13)>0,"9031501","") -> 9031501 | AD13: =IF(ISBLANK(Requerimiento_Det!N13),"",VLOOKUP(Requerimiento_Det!N13,Tabla1[#All],2,FALSE)) -> 1031100326 | AE13: =IF(ISBLANK(Requerimiento_Det!P13),"",VLOOKUP(Requerimiento_Det!P13,Tabla18[#All],2,FALSE)) -> BTRU
... A20: 1 | B20: =IF(LEN(Requerimiento_Det!B20)>0,Requerimiento_Det!B20,"") -> 19 | C20: =IF(ISBLANK(Requerimiento_Det!C20),"",VLOOKUP(Requerimiento_Det!C20,Tabla3[#All],2,FALSE)) -> 10000000 | D20: =IF(LEN(Requerimiento_Det!D20)>0,Requerimiento_Det!D20,"") | E20: =IF(ISBLANK(Requerimiento_Det!E20),"",VLOOKUP(Requerimiento_Det!E20,Tabla13[#All],2,FALSE)) -> 0 | F20: =IF(ISBLANK(Requerimiento_Det!F20),"",VLOOKUP(Requerimiento_Det!F20,Tabla12[#All],2,FALSE)) -> 2806 | G20: =IF(ISBLANK(Requerimiento_Det!G20),"",VLOOKUP(Requerimiento_Det!G20,Tabla14[#All],2,FALSE)) -> UNI | H20: =IF(LEN(Requerimiento_Det!H20)>0,Requerimiento_Det!H20,"") -> Sullana 287583 TALARA CHICLAYO TALARA | I20: =IF(ISBLANK(Requerimiento_Det!I20),"",VLOOKUP(Requerimiento_Det!I20,Tabla5[#All],2,FALSE)) -> C | J20: =IF(LEN(C20)>0,"N","") -> N | K20: =IF(LEN(Requerimiento_Det!J20)>0,Requerimiento_Det!J20,"") -> 1 | L20: =IF(LEN(C20)>0,"0.00","") -> 0.00 | M20: =IF(LEN(C20)>0,"0.00","") -> 0.00 | N20: =IF(LEN(C20)>0,"0.00","") -> 0.00 | O20: =IF(LEN(N20)>0,K20*N20,"") -> 0 | P20: =IF(LEN(C20)>0,"0","") -> 0 | Q20: =IF(LEN(C20)>0,"0","") -> 0 | R20: =IF(LEN(C20)>0,"0.000000","") -> 0.000000 | S20: =IF(LEN(C20)>0,"0.000000","") -> 0.000000 | T20: =IF(LEN(C20)>0,"0","") -> 0 | U20: =IF(LEN(C20)>0,"0","") -> 0 | V20: =IF(LEN(C20)>0,"S","") -> S | W20: =IF(LEN(Requerimiento_Det!L20)>0,Requerimiento_Det!L20,"") -> Sullana 287583 TALARA CHICLAYO TALARA | X20: =IF(ISBLANK(Requerimiento_Det!M20),"",VLOOKUP(Requerimiento_Det!M20,Tabla8[#All],2,FALSE)) -> 010201 | Y20: =IF(LEN(C20)>0,"PR","") -> PR | Z20: =IF(LEN(C20)>0,"DEMO","") -> DEMO | AA20: =IF(LEN(C20)>0,"N","") -> N | AB20: =IF(LEN(C20)>0,"N","") -> N | AC20: =IF(LEN(C20)>0,"9031501","") -> 9031501 | AD20: =IF(ISBLANK(Requerimiento_Det!N20),"",VLOOKUP(Requerimiento_Det!N20,Tabla1[#All],2,FALSE)) -> 1031100295 | AE20: =IF(ISBLANK(Requerimiento_Det!P20),"",VLOOKUP(Requerimiento_Det!P20,Tabla18[#All],2,FALSE)) -> BTRU
A21: =IF(LEN(Requerimiento_Det!A21)>0,Requerimiento_Det!A21,"") -> 1 | B21: =IF(LEN(Requerimiento_Det!B21)>0,Requerimiento_Det!B21,"") -> 20 | C21: =IF(ISBLANK(Requerimiento_Det!C21),"",VLOOKUP(Requerimiento_Det!C21,Tabla3[#All],2,FALSE)) -> 10000000 | D21: =IF(LEN(Requerimiento_Det!D21)>0,Requerimiento_Det!D21,"") | E21: =IF(ISBLANK(Requerimiento_Det!E21),"",VLOOKUP(Requerimiento_Det!E21,Tabla13[#All],2,FALSE)) -> 0 | F21: =IF(ISBLANK(Requerimiento_Det!F21),"",VLOOKUP(Requerimiento_Det!F21,Tabla12[#All],2,FALSE)) -> 2806 | G21: =IF(ISBLANK(Requerimiento_Det!G21),"",VLOOKUP(Requerimiento_Det!G21,Tabla14[#All],2,FALSE)) -> UNI | H21: =IF(LEN(Requerimiento_Det!H21)>0,Requerimiento_Det!H21,"") -> Pacanguilla 287206 TRUJILLO PIURA TRUJILLO | I21: =IF(ISBLANK(Requerimiento_Det!I21),"",VLOOKUP(Requerimiento_Det!I21,Tabla5[#All],2,FALSE)) -> C | J21: =IF(LEN(C21)>0,"N","") -> N | K21: =IF(LEN(Requerimiento_Det!J21)>0,Requerimiento_Det!J21,"") -> 1 | L21: =IF(LEN(C21)>0,"0.00","") -> 0.00 | M21: =IF(LEN(C21)>0,"0.00","") -> 0.00 | N21: =IF(LEN(C21)>0,"0.00","") -> 0.00 | O21: =IF(LEN(N21)>0,K21*N21,"") -> 0 | P21: =IF(LEN(C21)>0,"0","") -> 0 | Q21: =IF(LEN(C21)>0,"0","") -> 0 | R21: =IF(LEN(C21)>0,"0.000000","") -> 0.000000 | S21: =IF(LEN(C21)>0,"0.000000","") -> 0.000000 | T21: =IF(LEN(C21)>0,"0","") -> 0 | U21: =IF(LEN(C21)>0,"0","") -> 0 | V21: =IF(LEN(C21)>0,"S","") -> S | W21: =IF(LEN(Requerimiento_Det!L21)>0,Requerimiento_Det!L21,"") -> Pacanguilla 287206 TRUJILLO PIURA TRUJILLO | X21: =IF(ISBLANK(Requerimiento_Det!M21),"",VLOOKUP(Requerimiento_Det!M21,Tabla8[#All],2,FALSE)) -> 010201 | Y21: =IF(LEN(C21)>0,"PR","") -> PR | Z21: =IF(LEN(C21)>0,"DEMO","") -> DEMO | AA21: =IF(LEN(C21)>0,"N","") -> N | AB21: =IF(LEN(C21)>0,"N","") -> N | AC21: =IF(LEN(C21)>0,"9031501","") -> 9031501 | AD21: =IF(ISBLANK(Requerimiento_Det!N21),"",VLOOKUP(Requerimiento_Det!N21,Tabla1[#All],2,FALSE)) -> 1031100337 | AE21: =IF(ISBLANK(Requerimiento_Det!P21),"",VLOOKUP(Requerimiento_Det!P21,Tabla18[#All],2,FALSE)) -> BTRU
